<?xml version="1.0"?>

<robot xmlns:xacro="http://ros.org/wiki/xacro">

  <xacro:macro name="ball_macro" params="namespace parent_link ball_radius ball_mass cable_length *origin">
    <link name="${namespace}/ball_link">
      <inertial>
        <mass value="${ball_mass}" />
        <!-- center of mass (com) is defined w.r.t. link local coordinate system -->
        <!-- give a little y-offset to make the top precess -->
        <origin xyz="0 0 0" rpy="0 0 0" /> 
        <inertia  ixx="1" ixy="0.0"  ixz="0.0"  iyy="1"  iyz="0.0"  izz="1" />
      </inertial>
      <visual>
        <!-- visual origin is defined w.r.t. link local coordinate system -->
        <origin xyz="0 0 0" rpy="0 0 0" />
        <geometry>
          <sphere radius="${ball_radius}"/>
        </geometry>
      </visual>
      <collision>
        <!-- collision origin is defined w.r.t. link local coordinate system -->
        <origin xyz="0 0 0" rpy="0 0 0" />
        <geometry>
          <sphere radius="${ball_radius}"/>
        </geometry>
      </collision>
    </link>
    <joint name="${namespace}/ball_joint" type="floating">
      <xacro:insert_block name="origin" />
      <parent link="${parent_link}" />
      <child link="${namespace}/ball_link" />
    </joint>
    <gazebo>
      <plugin name="${namespace}_cable_plugin" filename="librotors_gazebo_cable_plugin.so">
        <robotNamespace>${namespace}</robotNamespace>
        <parentLinkName>${namespace}/base_link</parentLinkName>
        <linkName>${namespace}/ball_link</linkName>
        <ballMass>${ball_mass}</ballMass>
        <cableLength>${cable_length}</cableLength>
      </plugin>
    </gazebo>
    <gazebo reference="${namespace}/ball_link">
      <mu1>10</mu1>
      <mu2>10</mu2>
      <material>Gazebo/Red</material>
      <turnGravityOff>false</turnGravityOff>
    </gazebo>
  </xacro:macro>

</robot>